07:40:45 PM:ERROR[conexion.py:26] Ocurrio un error: 
07:40:57 PM:ERROR[conexion.py:26] Ocurrio un error: 
07:42:21 PM:ERROR[conexion.py:26] Ocurrio un error: 
07:42:37 PM:ERROR[conexion.py:28] Ocurrio un error: 
07:43:05 PM:DEBUG[Persona.py:55] 
            Id Persona: 1,
            Nombre: Juan,
            Apellido: Perez,
            Email: jperez@mail.com
        
07:43:05 PM:DEBUG[Persona.py:57] 
            Id Persona: None,
            Nombre: Jose,
            Apellido: Lepez,
            Email: ljose@mail.com
        
07:43:05 PM:DEBUG[Persona.py:59] 
            Id Persona: 1,
            Nombre: None,
            Apellido: None,
            Email: None
        
07:43:12 PM:DEBUG[logger_base.py:17] Mensaje a nivel debug
07:43:12 PM:INFO[logger_base.py:18] Mensaje a nivel info
07:43:12 PM:WARNING[logger_base.py:19] Mensaje a nivel warning
07:43:12 PM:ERROR[logger_base.py:20] Mensaje a nivel error
07:43:12 PM:CRITICAL[logger_base.py:21] Mensaje a nivel critical
07:43:19 PM:ERROR[conexion.py:28] Ocurrio un error: 
07:51:39 PM:ERROR[conexion.py:28] Ocurrio un error: connection to server at "127.0.0.1", port 5432 failed: FATAL:  database "test_bd" does not exist

